<?xml version="1.0" ?>
<robot name="AGV" xmlns:xacro="http://ros.org/wiki/xacro">

  <link name="base_footprint"/>

  <joint name="base_joint" type="fixed">
    <parent link="base_footprint"/>
    <child link="base_link" />
    <origin xyz="0 0 0" rpy="0 0 0"/>
  </joint>

  <link name="base_link">
    <visual>
      <origin xyz="0 0 0" rpy="0 0 0"/>
      <geometry>
        <mesh filename="package://scl_agv/meshes/AGV_model.stl" scale="0.01 0.01 0.01"/>
      </geometry>
      <material name="white">
           <color rgba="1 1 1 1"/>
      </material>
    </visual>
  </link>
  
  <joint name="laser_joint_1" type="fixed">
    <parent link="base_link"/>
    <child link="base_scan" />
    <origin xyz="0.1808 0.2848 0.111" rpy="0 0 0.707"/>

  </joint>

  <link name="base_scan">
    <visual>
      <origin xyz="0 0 0" rpy="1.5708 0 0"/>
      <geometry>
        <mesh filename="package://scl_agv/meshes/laser_scan.stl" scale="0.01 0.01 0.01"/>
      </geometry>
      <material name="blue">
           <color rgba="0 0 1 1"/>
      </material>
    </visual>
  </link>
  
  <joint name="laser_joint_2" type="fixed">
    <parent link="base_link"/>
    <child link="laser_scan_2" />
    <origin xyz="-0.3888 -0.2848 0.111" rpy="0 0 -2.3561"/>
  </joint>

  <link name="laser_scan_2">
    <visual>
      <origin xyz="0 0 0" rpy="1.5708 0 0"/>
      <geometry>
        <mesh filename="package://scl_agv/meshes/laser_scan.stl" scale="0.01 0.01 0.01"/>
      </geometry>
      <material name="blue">
           <color rgba="0 0 1 1"/>
      </material>
    </visual>
  </link>
  
  <joint name="wheel_left_joint" type="continuous">
    <parent link="base_link"/>
    <child link="main_wheel_left" />
    <origin xyz="0 0.1161 0.145" rpy="1.5708 0 1.5708"/>
  </joint>

  <link name="main_wheel_left">
    <visual>
      <origin xyz="0 0 0" rpy="0 0 0"/>
      <geometry>
        <mesh filename="package://scl_agv/meshes/main_wheel.stl" scale="0.01 0.01 0.01"/>
      </geometry>
      <material name="black">
           <color rgba="0 0 0 1"/>
      </material>
    </visual>
  </link>
  
  <joint name="wheel_right_joint" type="continuous">
    <parent link="base_link"/>
    <child link="main_wheel_right" />
    <origin xyz="0 -0.1161 0.145" rpy="1.5708 0 1.5708"/>
  </joint>

  <link name="main_wheel_right">
    <visual>
      <origin xyz="0 0 0" rpy="0 0 0"/>
      <geometry>
        <mesh filename="package://scl_agv/meshes/main_wheel.stl" scale="0.01 0.01 0.01"/>
      </geometry>
      <material name="black">
           <color rgba="0 0 0 1"/>
      </material>
    </visual>
  </link>
  
  <joint name="aid_left_joint" type="fixed">
    <parent link="base_link"/>
    <child link="aid_wheel_left" />
    <origin xyz="-0.362 0.258 0.079" rpy="1.5708 0 1.5708"/>
  </joint>

  <link name="aid_wheel_left">
    <visual>
      <origin xyz="0 0 0" rpy="0 0 0"/>
      <geometry>
        <mesh filename="package://scl_agv/meshes/aid_wheel.stl" scale="0.01 0.01 0.01"/>
      </geometry>
      <material name="black">
           <color rgba="0 0 0 1"/>
      </material>
    </visual>
  </link>
  
  <joint name="aid_right_joint" type="fixed">
    <parent link="base_link"/>
    <child link="aid_wheel_right" />
    <origin xyz="-0.362 -0.258 0.079" rpy="1.5708 0 1.5708"/>
  </joint>

  <link name="aid_wheel_right">
    <visual>
      <origin xyz="0 0 0" rpy="0 0 0"/>
      <geometry>
        <mesh filename="package://scl_agv/meshes/aid_wheel.stl" scale="0.01 0.01 0.01"/>
      </geometry>
      <material name="black">
           <color rgba="0 0 0 1"/>
      </material>
    </visual>
  </link>
  
  <joint name="sick_laser_joint" type="fixed">
    <parent link="base_link"/>
    <child link="sick_scan" />
    <origin xyz="0.1808 0 0.111" rpy="0 0 0"/>
  </joint>

  <link name="sick_scan">
    <visual>
      <origin xyz="0 0 0" rpy="1.5708 0 0"/>
      <geometry>
        <mesh filename="package://scl_agv/meshes/laser_scan.stl" scale="0.01 0.01 0.01"/>
      </geometry>
      <material name="blue">
           <color rgba="0 0 1 1"/>
      </material>
    </visual>
  </link>
  
  
  
</robot>
